<?xml version="1.0" ?>
<!-- =================================================================================== -->
<!-- |    This document was autogenerated by xacro from /workspaces/edna2023/src/edna_description/urdf/robots/edna.urdf.xacro | -->
<!-- |    EDITING THIS FILE BY HAND IS NOT RECOMMENDED                                 | -->
<!-- =================================================================================== -->
<robot name="edna">
  <!-- Specify some standard inertial calculations https://en.wikipedia.org/wiki/List_of_moments_of_inertia -->
  <!-- These make use of xacro's mathematical functionality -->
  <material name="black">
    <color rgba="0.0 0.0 0.0 1.0"/>
  </material>
  <material name="blue">
    <color rgba="0.13725490196078433 0.43137254901960786 0.5882352941176471 1.0"/>
  </material>
  <material name="green">
    <color rgba="0.0 0.8 0.0 1.0"/>
  </material>
  <material name="grey">
    <color rgba="0.2 0.2 0.2 1.0"/>
  </material>
  <material name="yellow">
    <color rgba="1.0 0.8431372549019608 0.0 1"/>
  </material>
  <material name="orange">
    <color rgba="0.9529411764705882 0.5294117647058824 0.1843137254901961 1"/>
  </material>
  <material name="brown">
    <color rgba="0.8705882352941177 0.8117647058823529 0.7647058823529411 1.0"/>
  </material>
  <material name="red">
    <color rgba="0.8 0.0 0.0 1.0"/>
  </material>
  <material name="white">
    <color rgba="1.0 1.0 1.0 1.0"/>
  </material>
  <material name="silver">
    <color rgba="0.700 0.700 0.700 1.000"/>
  </material>
  <material name="zed2i_mat">
    <color rgba="0.25 0.25 0.25 0.99"/>
  </material>
  <!-- Made up values, replace with real ones later. -->
  <!-- X IS FORWARD -->
  <!-- Y IS LEFT -->
  <!-- Z IS UP -->
  <!-- Chassis -->
  <link name="base_link"/>
  <link name="swerve_chassis_link">
    <inertial>
      <origin rpy="0 0 0" xyz="0 0 0.02794"/>
      <mass value="19.0508795"/>
      <inertia ixx="0.8663421337789339" ixy="0.0" ixz="0.0" iyy="0.8663421337789339" iyz="0.0" izz="1.7227696361205036"/>
    </inertial>
    <visual>
      <origin rpy="1.5707963267948966 0 0" xyz="0.061605 0.53866 -0.34976"/>
      <geometry>
        <mesh filename="package://edna_description/meshes/SwerveChassis.stl" scale="0.001 0.001 0.001"/>
      </geometry>
      <material name="red"/>
    </visual>
    <collision>
      <origin rpy="0 0 0" xyz="0 0 0.02794"/>
      <geometry>
        <box size="0.7366 0.7366 0.05588 "/>
      </geometry>
    </collision>
  </link>
  <joint name="swerve_chassis_joint" type="fixed">
    <parent link="base_link"/>
    <child link="swerve_chassis_link"/>
    <origin rpy="0 0 0" xyz="0 0 0"/>
  </joint>
  <link name="front_left_axle_link">
    <visual>
      <origin rpy="3.141592653589793 0 1.5707963267948966" xyz="0 0 0"/>
      <geometry>
        <mesh filename="package://edna_description/meshes/SwerveAxle.stl" scale="0.001 0.001 0.001"/>
      </geometry>
      <material name="blue"/>
    </visual>
    <inertial>
      <origin rpy="0 0 0" xyz="0 0 -0.015"/>
      <mass value="0.23739"/>
      <inertia ixx="0.000166173" ixy="0.0" ixz="0.0" iyy="0.000166173" iyz="0.0" izz="0.00029673750000000005"/>
    </inertial>
  </link>
  <joint name="front_left_axle_joint" type="continuous">
    <parent link="swerve_chassis_link"/>
    <child link="front_left_axle_link"/>
    <origin rpy="0 0 0" xyz="0.301625 0.301625 0.06905599999999999"/>
    <axis xyz="0 0 -1"/>
    <dynamics friction="0.1"/>
  </joint>
  <link name="front_left_wheel_link">
    <visual>
      <origin rpy="0 0.7853981633974483 1.5707963267948966" xyz="0 -0.022 0"/>
      <geometry>
        <mesh filename="package://edna_description/meshes/SwerveWheel.stl" scale="0.001 0.001 0.001"/>
      </geometry>
      <material name="yellow"/>
    </visual>
    <collision>
      <origin rpy="1.5707963267948966 0 0" xyz="0 0 0"/>
      <geometry>
        <cylinder length="0.0381" radius="0.0508"/>
      </geometry>
    </collision>
    <inertial>
      <origin rpy="1.5707963267948966 0 0" xyz="0 0 0"/>
      <mass value="0.23133211"/>
      <inertia ixx="0.00017722989110402498" ixy="0.0" ixz="0.0" iyy="0.00017722989110402498" iyz="0.0" izz="0.0002984924481752"/>
    </inertial>
  </link>
  <joint name="front_left_wheel_joint" type="continuous">
    <parent link="front_left_axle_link"/>
    <child link="front_left_wheel_link"/>
    <origin rpy="0 0 0" xyz="0 0 -0.063"/>
    <axis xyz="0 1 0"/>
    <dynamics friction="0.1"/>
  </joint>
  <link name="front_right_axle_link">
    <visual>
      <origin rpy="3.141592653589793 0 1.5707963267948966" xyz="0 0 0"/>
      <geometry>
        <mesh filename="package://edna_description/meshes/SwerveAxle.stl" scale="0.001 0.001 0.001"/>
      </geometry>
      <material name="blue"/>
    </visual>
    <inertial>
      <origin rpy="0 0 0" xyz="0 0 -0.015"/>
      <mass value="0.23739"/>
      <inertia ixx="0.000166173" ixy="0.0" ixz="0.0" iyy="0.000166173" iyz="0.0" izz="0.00029673750000000005"/>
    </inertial>
  </link>
  <joint name="front_right_axle_joint" type="continuous">
    <parent link="swerve_chassis_link"/>
    <child link="front_right_axle_link"/>
    <origin rpy="0 0 0" xyz="0.301625 -0.301625 0.06905599999999999"/>
    <axis xyz="0 0 -1"/>
    <dynamics friction="0.1"/>
  </joint>
  <link name="front_right_wheel_link">
    <visual>
      <origin rpy="0 0.7853981633974483 1.5707963267948966" xyz="0 -0.022 0"/>
      <geometry>
        <mesh filename="package://edna_description/meshes/SwerveWheel.stl" scale="0.001 0.001 0.001"/>
      </geometry>
      <material name="yellow"/>
    </visual>
    <collision>
      <origin rpy="1.5707963267948966 0 0" xyz="0 0 0"/>
      <geometry>
        <cylinder length="0.0381" radius="0.0508"/>
      </geometry>
    </collision>
    <inertial>
      <origin rpy="1.5707963267948966 0 0" xyz="0 0 0"/>
      <mass value="0.23133211"/>
      <inertia ixx="0.00017722989110402498" ixy="0.0" ixz="0.0" iyy="0.00017722989110402498" iyz="0.0" izz="0.0002984924481752"/>
    </inertial>
  </link>
  <joint name="front_right_wheel_joint" type="continuous">
    <parent link="front_right_axle_link"/>
    <child link="front_right_wheel_link"/>
    <origin rpy="0 0 0" xyz="0 0 -0.063"/>
    <axis xyz="0 1 0"/>
    <dynamics friction="0.1"/>
  </joint>
  <link name="rear_left_axle_link">
    <visual>
      <origin rpy="3.141592653589793 0 1.5707963267948966" xyz="0 0 0"/>
      <geometry>
        <mesh filename="package://edna_description/meshes/SwerveAxle.stl" scale="0.001 0.001 0.001"/>
      </geometry>
      <material name="blue"/>
    </visual>
    <inertial>
      <origin rpy="0 0 0" xyz="0 0 -0.015"/>
      <mass value="0.23739"/>
      <inertia ixx="0.000166173" ixy="0.0" ixz="0.0" iyy="0.000166173" iyz="0.0" izz="0.00029673750000000005"/>
    </inertial>
  </link>
  <joint name="rear_left_axle_joint" type="continuous">
    <parent link="swerve_chassis_link"/>
    <child link="rear_left_axle_link"/>
    <origin rpy="0 0 0" xyz="-0.301625 0.301625 0.06905599999999999 "/>
    <axis xyz="0 0 -1"/>
    <dynamics friction="0.1"/>
  </joint>
  <link name="rear_left_wheel_link">
    <visual>
      <origin rpy="0 0.7853981633974483 1.5707963267948966" xyz="0 -0.022 0"/>
      <geometry>
        <mesh filename="package://edna_description/meshes/SwerveWheel.stl" scale="0.001 0.001 0.001"/>
      </geometry>
      <material name="yellow"/>
    </visual>
    <collision>
      <origin rpy="1.5707963267948966 0 0" xyz="0 0 0"/>
      <geometry>
        <cylinder length="0.0381" radius="0.0508"/>
      </geometry>
    </collision>
    <inertial>
      <origin rpy="1.5707963267948966 0 0" xyz="0 0 0"/>
      <mass value="0.23133211"/>
      <inertia ixx="0.00017722989110402498" ixy="0.0" ixz="0.0" iyy="0.00017722989110402498" iyz="0.0" izz="0.0002984924481752"/>
    </inertial>
  </link>
  <joint name="rear_left_wheel_joint" type="continuous">
    <parent link="rear_left_axle_link"/>
    <child link="rear_left_wheel_link"/>
    <origin rpy="0 0 0" xyz="0 0 -0.063"/>
    <axis xyz="0 1 0"/>
    <dynamics friction="0.1"/>
  </joint>
  <link name="rear_right_axle_link">
    <visual>
      <origin rpy="3.141592653589793 0 1.5707963267948966" xyz="0 0 0"/>
      <geometry>
        <mesh filename="package://edna_description/meshes/SwerveAxle.stl" scale="0.001 0.001 0.001"/>
      </geometry>
      <material name="blue"/>
    </visual>
    <inertial>
      <origin rpy="0 0 0" xyz="0 0 -0.015"/>
      <mass value="0.23739"/>
      <inertia ixx="0.000166173" ixy="0.0" ixz="0.0" iyy="0.000166173" iyz="0.0" izz="0.00029673750000000005"/>
    </inertial>
  </link>
  <joint name="rear_right_axle_joint" type="continuous">
    <parent link="swerve_chassis_link"/>
    <child link="rear_right_axle_link"/>
    <origin rpy="0 0 0" xyz="-0.301625 -0.301625 0.06905599999999999"/>
    <axis xyz="0 0 -1"/>
    <dynamics friction="0.1"/>
  </joint>
  <link name="rear_right_wheel_link">
    <visual>
      <origin rpy="0 0.7853981633974483 1.5707963267948966" xyz="0 -0.022 0"/>
      <geometry>
        <mesh filename="package://edna_description/meshes/SwerveWheel.stl" scale="0.001 0.001 0.001"/>
      </geometry>
      <material name="yellow"/>
    </visual>
    <collision>
      <origin rpy="1.5707963267948966 0 0" xyz="0 0 0"/>
      <geometry>
        <cylinder length="0.0381" radius="0.0508"/>
      </geometry>
    </collision>
    <inertial>
      <origin rpy="1.5707963267948966 0 0" xyz="0 0 0"/>
      <mass value="0.23133211"/>
      <inertia ixx="0.00017722989110402498" ixy="0.0" ixz="0.0" iyy="0.00017722989110402498" iyz="0.0" izz="0.0002984924481752"/>
    </inertial>
  </link>
  <joint name="rear_right_wheel_joint" type="continuous">
    <parent link="rear_right_axle_link"/>
    <child link="rear_right_wheel_link"/>
    <origin rpy="0 0 0" xyz="0 0 -0.063"/>
    <axis xyz="0 1 0"/>
    <dynamics friction="0.1"/>
  </joint>
  <!-- Camera mounting point (the threaded screw hole in the bottom) -->
  <link name="zed_base_link"/>
  <joint name="zed_base_joint" type="fixed">
    <parent link="swerve_chassis_link"/>
    <child link="zed_base_link"/>
    <origin rpy="0 0 0" xyz="0 0 0.3"/>
  </joint>
  <!-- Camera Center -->
  <link name="zed_camera_center">
    <visual>
      <origin rpy="0 0 0" xyz="-0.01 0 0"/>
      <geometry>
        <mesh filename="package://edna_description/meshes/zed2i.stl"/>
      </geometry>
      <material name="zed2i_mat"/>
    </visual>
    <collision>
      <geometry>
        <mesh filename="package://edna_description/meshes/zed2i.stl"/>
      </geometry>
    </collision>
  </link>
  <joint name="zed_camera_center_joint" type="fixed">
    <parent link="zed_base_link"/>
    <child link="zed_camera_center"/>
    <origin rpy="0 0.0 0" xyz="0 0 0.015"/>
  </joint>
  <!-- Left Camera -->
  <link name="zed_left_camera_frame"/>
  <joint name="zed_left_camera_joint" type="fixed">
    <parent link="zed_camera_center"/>
    <child link="zed_left_camera_frame"/>
    <origin rpy="0 0 0" xyz="0 0.06 0"/>
  </joint>
  <link name="zed_left_camera_optical_frame"/>
  <joint name="zed_left_camera_optical_joint" type="fixed">
    <origin rpy="1.5707963267948966 0.0 1.5707963267948966" xyz="-0.01 0 0"/>
    <parent link="zed_left_camera_frame"/>
    <child link="zed_left_camera_optical_frame"/>
  </joint>
  <!-- Right Camera -->
  <link name="zed_right_camera_frame"/>
  <joint name="zed_right_camera_joint" type="fixed">
    <parent link="zed_camera_center"/>
    <child link="zed_right_camera_frame"/>
    <origin rpy="0 0 0" xyz="0 -0.06 0"/>
  </joint>
  <link name="zed_right_camera_optical_frame"/>
  <joint name="zed_right_camera_optical_joint" type="fixed">
    <origin rpy="1.5707963267948966 0.0 1.5707963267948966" xyz="-0.01 0 0"/>
    <parent link="zed_right_camera_frame"/>
    <child link="zed_right_camera_optical_frame"/>
  </joint>
  <ros2_control name="swerve_drive" type="system">
    <hardware>
      <plugin>swerve_hardware/IsaacDriveHardware</plugin>
      <param name="example_param_hw_start_duration_sec">3.0</param>
      <param name="example_param_hw_stop_duration_sec">3.0</param>
    </hardware>
    <joint name="front_right_wheel_joint">
      <command_interface name="velocity">
        <param name="min">-1</param>
        <param name="max">1</param>
      </command_interface>
      <state_interface name="position"/>
      <state_interface name="velocity"/>
    </joint>
    <joint name="rear_left_wheel_joint">
      <command_interface name="velocity">
        <param name="min">-1</param>
        <param name="max">1</param>
      </command_interface>
      <state_interface name="position"/>
      <state_interface name="velocity"/>
    </joint>
    <joint name="front_left_wheel_joint">
      <command_interface name="velocity">
        <param name="min">-1</param>
        <param name="max">1</param>
      </command_interface>
      <state_interface name="position"/>
      <state_interface name="velocity"/>
    </joint>
    <joint name="rear_right_wheel_joint">
      <command_interface name="velocity">
        <param name="min">-1</param>
        <param name="max">1</param>
      </command_interface>
      <state_interface name="position"/>
      <state_interface name="velocity"/>
    </joint>
    <joint name="front_right_axle_joint">
      <command_interface name="position">
        <param name="min">-1</param>
        <param name="max">1</param>
      </command_interface>
      <state_interface name="position"/>
      <state_interface name="velocity"/>
    </joint>
    <joint name="rear_left_axle_joint">
      <command_interface name="position">
        <param name="min">-1</param>
        <param name="max">1</param>
      </command_interface>
      <state_interface name="position"/>
      <state_interface name="velocity"/>
    </joint>
    <joint name="front_left_axle_joint">
      <command_interface name="position">
        <param name="min">-1</param>
        <param name="max">1</param>
      </command_interface>
      <state_interface name="position"/>
      <state_interface name="velocity"/>
    </joint>
    <joint name="rear_right_axle_joint">
      <command_interface name="position">
        <param name="min">-1</param>
        <param name="max">1</param>
      </command_interface>
      <state_interface name="position"/>
      <state_interface name="velocity"/>
    </joint>
  </ros2_control>
</robot>
